<?xml version="1.0"?>
<robot xmlns:xacro="http://www.ros.org/wiki/xacro">

    <link name="base_link"></link>


    <joint name="base_to_chassis" type="fixed">
        <parent link="base_link" />
        <child link="chassis" />
        <origin xyz="0 0 0.15" />
    </joint>


    <link name="chassis">
        <visual>
            <geometry>
                <box size="2 1 0.5" />
            </geometry>
            <material name="white" />
        </visual>
        <collision>
            <geometry>
                <box size="2 1 0.5" />
            </geometry>
        </collision>
        <inertial>
            <mass value="1.15" />
            <inertia ixx="0.13" ixy="0.0" ixz="0.0" iyy="0.7" iyz="0.0" izz="0.5" />
        </inertial>
    </link>

    <gazebo reference="chassis">
        <material>Gazebo/Orange</material>
    </gazebo>


    <joint name="base_to_left_wheel" type="continuous">
        <parent link="base_link" />
        <child link="left_wheel" />
        <origin rpy="-1.57075 0 0" xyz="0 0.625 0" />
        <axis rpy="0 0 0" xyz="0 0 1" />
        <limit effort="1000.0" lower="-1e50" upper="1e50" velocity="30"/>
        <dynamics damping="0.0" friction="0.0"/>
    </joint>

    <!-- <transmission name="base_to_left_wheel_trans">
        <type>transmission_interface/SimpleTransmission</type>
        <actuator name="base_to_left_wheel_motor">
            <mechanicalReduction>1</mechanicalReduction>
        </actuator>
        <joint name="base_to_left_wheel">
            <hardwareInterface>VelocityJointInterface</hardwareInterface>
        </joint>
    </transmission> -->


    <link name="left_wheel">
        <visual>
            <geometry>
                <sphere radius="0.3" />
            </geometry>
            <material name="blue" />
        </visual>
        <collision>
            <geometry>
                <sphere radius="0.3" />
            </geometry>
        </collision>
        <inertial>
            <mass value="2" />
            <inertia ixx="0.15" ixy="0.0" ixz="0.0" iyy="0.15" iyz="0.0" izz="0.5" />
        </inertial>
    </link>

    <gazebo reference="left_wheel">
        <mu1 value="10000.0" />
        <mu2 value="10000.0" />
        <kp value="1e13" />
        <kd value="1" />
        <material>Gazebo/Black</material>
    </gazebo>


    <joint name="base_to_right_wheel" type="continuous">
        <parent link="base_link" />
        <child link="right_wheel" />
        <origin rpy="-1.57075 0 0" xyz="0 -0.625 0" />
        <axis rpy="0 0 0" xyz="0 0 1" />
        <limit effort="1000.0" lower="-1e50" upper="1e50" velocity="30"/>
        <dynamics damping="0.0" friction="0.0"/>
    </joint>

    <!-- <transmission name="base_to_right_wheel_trans">
        <type>transmission_interface/SimpleTransmission</type>
        <actuator name="base_to_right_wheel_motor">
            <mechanicalReduction>1</mechanicalReduction>
        </actuator>
        <joint name="base_to_right_wheel">
            <hardwareInterface>VelocityJointInterface</hardwareInterface>
        </joint>
    </transmission> -->


    <link name="right_wheel">
        <collision>
            <geometry>
                <sphere radius="0.3" />
            </geometry>
        </collision>
        <visual>
            <geometry>
                <sphere radius="0.3" />
            </geometry>
            <material name="blue" />
        </visual>
        <inertial>
            <mass value="2" />
            <inertia ixx="0.15" ixy="0.0" ixz="0.0" iyy="0.15" iyz="0.0" izz="0.15" />
        </inertial>
    </link>

    <gazebo reference="right_wheel">
        <mu1 value="10000.0" />
        <mu2 value="10000.0" />
        <kp value="1e13" />
        <kd value="1" />
        <material>Gazebo/Black</material>
    </gazebo>


    <joint name="base_to_caster_wheel" type="fixed">
        <parent link="base_link" />
        <child link="caster_wheel" />
        <origin rpy="0 0 0" xyz="-1.5 0 -0.1" />
    </joint>


    <link name="caster_wheel">
        <collision>
            <geometry>
                <sphere radius="0.2" />
            </geometry>
        </collision>
        <visual>
            <geometry>
                <sphere radius="0.2" />
            </geometry>
            <material name="black" />
        </visual>
        <inertial>
            <mass value="3" />
            <inertia ixx="0.3" ixy="0.0" ixz="0.0" iyy="0.3" iyz="0.0" izz="0.3" />
        </inertial>
    </link>

    <gazebo reference="caster_wheel">
        <material>Gazebo/Black</material>
        <mu1>0.0</mu1>
    <mu2>0.0</mu2>
    </gazebo>


    <joint name="base_to_caster_wheel_2" type="fixed">
        <parent link="base_link" />
        <child link="caster_wheel_2" />
        <origin rpy="0 0 0" xyz="1.5 0 -0.1" />
    </joint>


    <link name="caster_wheel_2">
        <collision>
            <geometry>
                <sphere radius="0.2" />
            </geometry>
        </collision>
        <visual>
            <geometry>
                <sphere radius="0.2" />
            </geometry>
            <material name="black" />
        </visual>
        <inertial>
            <mass value="3" />
            <inertia ixx="0.3" ixy="0.0" ixz="0.0" iyy="0.3" iyz="0.0" izz="0.3" />
        </inertial>
    </link>

    <gazebo reference="caster_wheel_2">
        <material>Gazebo/Black</material>
        <mu1>0.0</mu1>
        <mu2>0.0</mu2>
    </gazebo>




</robot>
